{"uuid": "32b4b024-0e5a-4a09-99f0-2bde9a6ac0a8", "children": ["2c603fdd-cef6-4a3c-a232-1a08d08abaf9"], "befores": [{"name": "new_user", "status": "broken", "statusDetails": {"message": "requests.exceptions.ConnectionError: HTTPSConnectionPool(host='stellarburgers.nomoreparties.site', port=443): Max retries exceeded with url: /api/auth/register (Caused by NameResolutionError(\"<urllib3.connection.HTTPSConnection object at 0x000001C4CA6052D0>: Failed to resolve 'stellarburgers.nomoreparties.site' ([Errno 11001] getaddrinfo failed)\"))\n", "trace": "  File \"C:\\Users\\kuturma\\AppData\\Local\\Programs\\Python\\Python310\\lib\\site-packages\\pluggy\\_callers.py\", line 167, in _multicall\n    teardown.throw(outcome._exception)\n  File \"C:\\Users\\kuturma\\AppData\\Local\\Programs\\Python\\Python310\\lib\\site-packages\\_pytest\\setuponly.py\", line 36, in pytest_fixture_setup\n    return (yield)\n  File \"C:\\Users\\kuturma\\AppData\\Local\\Programs\\Python\\Python310\\lib\\site-packages\\pluggy\\_callers.py\", line 103, in _multicall\n    res = hook_impl.function(*args)\n  File \"C:\\Users\\kuturma\\AppData\\Local\\Programs\\Python\\Python310\\lib\\site-packages\\_pytest\\fixtures.py\", line 1140, in pytest_fixture_setup\n    result = call_fixture_func(fixturefunc, request, kwargs)\n  File \"C:\\Users\\kuturma\\AppData\\Local\\Programs\\Python\\Python310\\lib\\site-packages\\_pytest\\fixtures.py\", line 898, in call_fixture_func\n    fixture_result = fixturefunc(**kwargs)\n  File \"C:\\Users\\kuturma\\Desktop\\Diplom_2_develop2\\tests\\conftest.py\", line 23, in new_user\n    response = requests.post(TestEndpoint.REGISTER, json=payload)\n  File \"C:\\Users\\kuturma\\AppData\\Local\\Programs\\Python\\Python310\\lib\\site-packages\\requests\\api.py\", line 115, in post\n    return request(\"post\", url, data=data, json=json, **kwargs)\n  File \"C:\\Users\\kuturma\\AppData\\Local\\Programs\\Python\\Python310\\lib\\site-packages\\requests\\api.py\", line 59, in request\n    return session.request(method=method, url=url, **kwargs)\n  File \"C:\\Users\\kuturma\\AppData\\Local\\Programs\\Python\\Python310\\lib\\site-packages\\requests\\sessions.py\", line 589, in request\n    resp = self.send(prep, **send_kwargs)\n  File \"C:\\Users\\kuturma\\AppData\\Local\\Programs\\Python\\Python310\\lib\\site-packages\\requests\\sessions.py\", line 703, in send\n    r = adapter.send(request, **kwargs)\n  File \"C:\\Users\\kuturma\\AppData\\Local\\Programs\\Python\\Python310\\lib\\site-packages\\requests\\adapters.py\", line 700, in send\n    raise ConnectionError(e, request=request)\n"}, "start": 1753258782156, "stop": 1753258782163}], "start": 1753258782156, "stop": 1753258782582}